Workbook
Name _10.3GM: 'Look up (2)'!$BD$7
Name _10.3GM: 'Look up (2)'!$BD$7
Name _10.3GM: 'Look up (2)'!$BD$7
Name _10.3GM_HT: 'Look up (2)'!#REF!
Name _10.3GM_HT: #REF!
Name _10.3GM_HT: 'Look up (2)'!$BD$8
Name _10GM: 'Look up (2)'!#REF!
Name _10GM: #REF!
Name _10GM: 'Look up (2)'!$BD$5
Name _10GM_HT: 'Look up (2)'!#REF!
Name _10GM_HT: #REF!
Name _10GM_HT: 'Look up (2)'!$BD$6
Name _11GM: 'Look up (2)'!#REF!
Name _11GM: #REF!
Name _11GM: 'Look up (2)'!$BD$3
Name _11GM_HT: 'Look up (2)'!#REF!
Name _11GM_HT: #REF!
Name _11GM_HT: 'Look up (2)'!$BD$4
Name _12GM: 'Look up (2)'!#REF!
Name _12GM: #REF!
Name _12GM: 'Look up (2)'!$BD$2
Name _9.1_GM: 'Look up (2)'!#REF!
Name _9.1_GM: #REF!
Name _9.1_GM: 'Look up (2)'!$BD$9
Name _9.1_GM_HT: 'Look up (2)'!#REF!
Name _9.1_GM_HT: #REF!
Name _9.1_GM_HT: 'Look up (2)'!$BD$10
Name ADS: #REF!
Name ADS_: 'Look up (2)'!$B$24:$B$28
Name ADS_HLL: 'Look up (2)'!$AD$2:$AD$587
Name Attendance: OFFSET('DMS-2'!Full_Print,0,0,'DMS-2'!Last_Row)
Name Batching: 'Look up (2)'!$B$5:$B$11
Name Batching_Hopper_H_4101: 'Look up (2)'!$G$2:$G$1275
Name Batching_Hopper_H_4102: 'Look up (2)'!$H$2:$H$1246
Name Batter_Mixer_T_4108: 'Look up (2)'!$I$2:$I$1033
Name Batter_Mixer_T_4109: 'Look up (2)'!$J$2:$J$1091
Name Beg_Bal: #REF!
Name Beg_Bal: #REF!
Name Belt: #REF!
Name Book_Cooler: 'Look up (2)'!$O$2:$O$1228
Name Book_Cooler_: 'Look up (2)'!$B$13
Name Caramel: #REF!
Name Cbox_Checkweigher: 'Look up (2)'!$AS$2:$AS$1679
Name ChargingSystem: 'Look up (2)'!$D$2:$D$1000
Name Chilled_water: 'Look up (2)'!$AU$2:$AU$2039
Name Compressed_air: 'Look up (2)'!$AV$2:$AV$1274
Name Contimix: #REF!
Name Cooling_Tunnel_HLL: 'Look up (2)'!$X$2:$X$1844
Name Cooling_Tunnel_Samridhi: 'Look up (2)'!$W$2:$W$1739
Name CoolingTunnel: 'Look up (2)'!$B$21:$B$22
Name CT: #REF!
Name Cum_Int: #REF!
Name Cum_Int: #REF!
Name Cutter: #REF!
Name Cutter_: 'Look up (2)'!$B$15:$B$16
Name Cutter_HLL: 'Look up (2)'!$R$2:$R$1269
Name Cutter_Samridhi: 'Look up (2)'!$Q$2:$Q$1679
Name Data: #REF!
Name Data: #REF!
Name DayAxis: OFFSET(INDIRECT(#REF!&"!$a$1"),3,MATCH(#REF!,INDIRECT(#REF!&"!$1:$1"),0)-1,1,COUNTIF(INDIRECT(#REF!&"!$1:$1"),#REF!))

Sheet Report
A1: Date | B1: SHIFT | C1: PROD | D1: GE% | E1: UNPLANNED DOWNTIME | F1: quality loss | G1: OEE%
A2: 46260 | B2: A | C2: 5.9 | D2: 0.51754386 | E2: 237 | F2: 0.61 | G2: =((480-E2)*100%)/480*(C2*100%)/((480-E2)*11.4/480)*C2/(C2+F2) -> 0.46904897
A3: 46260 | B3: B | C3: =7.5+1.1 -> 8.6 | D3: 0.75438596 | E3: 60 | F3: 1.11 | G3: =((480-E3)*100%)/480*(C3*100%)/((480-E3)*11.4/480)*C3/(C3+F3) -> 0.66814823
A4: 46260 | B4: C | C4: =3.88+0.69 -> 4.57 | D4: 0.40087719 | E4: 200 | F4: 0.25 | G4: =((480-E4)*100%)/480*(C4*100%)/((480-E4)*11.4/480)*C4/(C4+F4) -> 0.38008481
A6: LOSS DETAILS
A7: Date | B7: shift | C7: Operation | D7: Equipment | E7: Failure Description | F7: line downtime | G7: Action Taken | H7: GE LOSS%(SHIFT)
A8: 46260 | B8: A | C8: Utility_ | D8: Compressed_air | E8: Air Pressure Low | F8: 20 | G8: Communication given to utiity team. Air pressure restored | H8: =F8/480 -> 0.041666667
A9: 46260 | B9: A | C9: HCM_ | D9: HCM5_ | E9: Pouch Leakage issue | F9: 36 | H9: =F9/480 -> 0.075
A10: 46260 | B10: A | C10: HCM_ | D10: HCM5_ | E10: Pouch Leakage issue | F10: 36 | H10: =F10/480 -> 0.075
A11: 46260 | B11: A | C11: Cutter_ | D11: Cutter_Samridhi | E11: Book Jamming @ Cutter | F11: 105 | G11: AD4 Quantity reduced from 200 to 190g | H11: =F11/480 -> 0.21875
A12: 46260 | B12: A | C12: ADS_ | D12: DCI4_ | E12: DU4R belt tracking issue | F12: 20 | G12: Tracking motor not available, Manual Adjustment done | H12: =F12/480 -> 0.041666667
A13: 46260 | B13: A | C13: TTLI_ | D13: TTLI1_ | E13: Glue unit not ready | F13: 10 | G13: ClosingSOV was faulty : Replaced, | H13: =F13/480 -> 0.020833333
A14: 46260 | B14: A | C14: HCM_ | D14: HCM2_ | E14: Code Misprint issue | F14: 10 | G14: Encoder to be replaced, Currently running @ 400 ppm | H14: =F14/480 -> 0.020833333
A15: 46260 | B15: B | C15: Oven_ | D15: Oven | E15: Bubble Scrapper Jam | F15: 60 | G15: Broken Scrapper Removed | H15: =F15/480 -> 0.125
A16: 46260 | B16: C | C16: Oven_ | D16: Oven | E16: Fire Tripping issue | F16: 200 | G16: Ignition Electrode mounting loose,ground issue,Electrode replaced | H16: =F16/480 -> 0.41666667

Sheet Shift Wise Downtime
A1: Date | B1: shift | C1: Operation | D1: Equipment | E1: Failure Description | F1: Loss Category | G1: Loss Type | H1: Equipment Class | I1: Equipment Downtime | J1: line downtime | K1: Action Taken
A2: 46260 | B2: A | C2: Utility_ | D2: Compressed_air | E2: Air Pressure Low | F2: Unplanned_Loss | G2: Line_Delays | I2: 20 | J2: 20 | K2: Communication given to utiity team. Air pressure restored
A3: 46260 | B3: A | C3: HCM_ | D3: HCM5_ | E3: Pouch Leakage issue | F3: Unplanned_Loss | G3: Operational_Losses | I3: 480 | J3: 36
A4: 46260 | B4: A | C4: HCM_ | D4: HCM5_ | E4: Pouch Leakage issue | F4: Unplanned_Loss | G4: Operational_Losses | I4: 480 | J4: 36
A5: 46260 | B5: A | C5: Cutter_ | D5: Cutter_Samridhi | E5: Book Jamming @ Cutter | F5: Unplanned_Loss | G5: Operational_Losses | I5: 105 | J5: 105 | K5: AD4 Quantity reduced from 200 to 190g
A6: 46260 | B6: A | C6: ADS_ | D6: DCI4_ | E6: DU4R belt tracking issue | F6: Unplanned_Loss | G6: Breakdowns | I6: 20 | J6: 20 | K6: Tracking motor not available, Manual Adjustment done
A7: 46260 | B7: A | C7: TTLI_ | D7: TTLI1_ | E7: Glue unit not ready | F7: Unplanned_Loss | G7: Breakdowns | I7: 40 | J7: 10 | K7: ClosingSOV was faulty : Replaced,
A8: 46260 | B8: A | C8: HCM_ | D8: HCM2_ | E8: Code Misprint issue | F8: Unplanned_Loss | G8: Breakdowns | I8: 40 | J8: 10 | K8: Encoder to be replaced, Currently running @ 400 ppm
A9: 46260 | B9: B | C9: Oven_ | D9: Oven | E9: Bubble Scrapper Jam | F9: Unplanned_Loss | G9: Breakdowns | I9: 60 | J9: 60 | K9: Broken Scrapper Removed
A10: 46260 | B10: C | C10: Oven_ | D10: Oven | E10: Fire Tripping issue | F10: Unplanned_Loss | G10: Breakdowns | I10: 200 | J10: 200 | K10: Ignition Electrode mounting loose,ground issue,Electrode replaced

Sheet Shift Wise-Data Sheet
F1: =SUBTOTAL(9,Table110[Plan]) -> 5464.9473 | G1: =SUBTOTAL(9,Table110[Volume Delivered (T)]) -> 5508.6196 | H1: =SUBTOTAL(1,Table110[GE - Target]) -> 0.76445593 | I1: =SUBTOTAL(1,Table110[GE - Actual]) -> 0.77841111 | J1: =SUBTOTAL(9,Table110[Legal Non-Operating Time]) -> 0 | K1: =SUBTOTAL(9,Table110[No Demand Time]) -> 40 | L1: =SUBTOTAL(9,Table110[Force Majeure]) -> 4 | N1: =SUBTOTAL(1,Table110[waste (%) - MTD]) -> 0.041427461 | Q1: =SUBTOTAL(9,Table110[TBM ACTIVITIES PLANNED]) -> 118 | R1: =SUBTOTAL(9,Table110[TBM ACTIVITIES COMPLETED]) -> 106 | S1: =SUBTOTAL(9,Table110[Hours Used]) -> 4804 | AJ1: =SUBTOTAL(9,Table110[Operating Time]) -> 3740.3775
A2: Date | B2: Day | C2: SHIFT | D2: SKU | E2: SOC (TPD) | F2: Plan | G2: Volume Delivered (T) | H2: GE - Target | I2: GE - Actual | J2: Legal Non-Operating Time | K2: No Demand Time | L2: Force Majeure | M2: Quality Loss (T) | N2: waste (%) - MTD | O2: Bulk on Floor (T) | P2: Offline Packing (MT) | Q2: rework on floor(T) | R2: TBM ACTIVITIES PLANNED | S2: TBM ACTIVITIES COMPLETED | T2: Hours Used | U2: Planned Maintenance | V2: Planned AM | W2: Sanitation | X2: Changeovers | Y2: Planned Stops | Z2: Consumables replacement | AA2: Start and Finish Production | AB2: PRODUCTION HOURS | AC2: Minor Stoppages | AD2: Breakdowns | AE2: Operational Losses | AF2: Line Delays | AG2: Labor Management | AH2: Material Shortages | AI2: Speed Loss (Hrs) | AJ2: Quality Loss (Hrs) | AK2: Operating Time | AL2: Operating Time (Planned) | AM2: CL Deployed at Line | AN2: CIL-DONE | AO2: centreline check | AP2: TBM ACTIVITIES PLANNED2 | AQ2: TBM ACTIVITIES COMPLETED2 | AR2: tbm-on time completion | AS2: mtbf | AT2: BOS | AU2: UNSAFE CONDITIONS REPORTED | AV2: OVERWEIGHT | AW2: MTBB | AX2: # Stops | AY2: MTTR | AZ2: R&R | BA2: GWF Month
A3: 46020 | B3: =IF(A3="","",TEXT(A3,"dddddd")) -> Monday | D3: _10GM_HT | E3: {=IFERROR(INDIRECT(D3),"")} -> 33.4 | F3: 14 | G3: 21.4 | H3: =IFERROR((Table110[[#This Row],[Plan]]/Table110[[#This Row],[Hours Used]])/(Table110[[#This Row],[SOC (TPD)]]/24),"") -> 0.41916168 | I3: =IFERROR((Table110[[#This Row],[Volume Delivered (T)]]/Table110[[#This Row],[Hours Used]])/(Table110[[#This Row],[SOC (TPD)]]/24),"") -> 0.64071856 | N3: 0.035 | R3: 1 | S3: 1 | T3: =IF(Table110[[#This Row],[SKU]]="",0,24-Table110[[#This Row],[Legal Non-Operating Time]]-Table110[[#This Row],[No Demand Time]]-Table110[[#This Row],[Force Majeure]]) -> 24 | W3: 9 | AB3: =Table110[[#This Row],[Hours Used]]-SUM(Table110[[#This Row],[Planned Maintenance]:[Start and Finish Production]]) -> 15 | AI3: =(Table110[[#This Row],[Hours Used]]-SUM(Table110[[#This Row],[Planned Maintenance]:[Start and Finish Production]])-SUM(Table110[[#This Row],[Minor Stoppages]:[Material Shortages]])-Table110[[#This Row],[Quality Loss (Hrs)]]-Table110[[#This Row],[Operating Time]])/3 -> -0.1257485 | AJ3: =IFERROR(IF(Table110[[#This Row],[SKU]]="",0,Table110[[#This Row],[Quality Loss (T)]]/(Table110[[#This Row],[SOC (TPD)]]/24)),"") -> 0 | AK3: =IFERROR(IF(Table110[[#This Row],[SKU]]="",0,Table110[[#This Row],[Volume Delivered (T)]]/(Table110[[#This Row],[SOC (TPD)]]/24)),"") -> 15.377246 | AL3: =IFERROR(Table110[[#This Row],[Operating Time]]/Table110[[#This Row],[PRODUCTION HOURS]],"") -> 1.0251497 | AN3: NO | AO3: NO | AP3: 6 | AQ3: 6 | AR3: 6 | AS3: =IFERROR(SUMIFS(#REF!,#REF!,'Shift Wise-Data Sheet'!A:A,#REF!,"Samridhi Perk Line")/SUMIFS(#REF!,#REF!,'Shift Wise-Data Sheet'!A:A,#REF!,"Samridhi Perk Line"),"") | AU3: 0 | AV3: =IFERROR(VLOOKUP(Table110[[#This Row],[Date]],'Overweight Data'!A1:G1096,6,FALSE),"") | AW3: =IFERROR( IF( OR(Table110[[#This Row],[Operating Time]]=0, (Table110[[#This Row],[Operating Time]]/IF(AD3<=1,AD3+1,AD3))*60=0), 1, ((Table110[[#This Row],[Operating Time]])/IF(AD3<=1,AD3+1,AD3))*60 ), "_") -> 922.63473 | AX3: =COUNTIFS('Downtime Data'!A:A,Table110[[#This Row],[Date]]) -> 1 | AY3: =IFERROR((SUM(Table110[[#This Row],[Minor Stoppages]:[Material Shortages]])/Table110[[#This Row],['# Stops]])*60,"") -> 0 | BA3: 46048
A4: 46021 | B4: =IF(A4="","",TEXT(A4,"dddddd")) -> Tuesday | D4: _10.3GM | E4: {=IFERROR(INDIRECT(D4),"")} -> 39.2 | F4: 32 | G4: 34.8 | H4: =IFERROR((Table110[[#This Row],[Plan]]/Table110[[#This Row],[Hours Used]])/(Table110[[#This Row],[SOC (TPD)]]/24),"") -> 0.81632653 | I4: =IFERROR((Table110[[#This Row],[Volume Delivered (T)]]/Table110[[#This Row],[Hours Used]])/(Table110[[#This Row],[SOC (TPD)]]/24),"") -> 0.8877551 | N4: 0.035 | R4: 1 | T4: =IF(Table110[[#This Row],[SKU]]="",0,24-Table110[[#This Row],[Legal Non-Operating Time]]-Table110[[#This Row],[No Demand Time]]-Table110[[#This Row],[Force Majeure]]) -> 24 | X4: 2 | AB4: =Table110[[#This Row],[Hours Used]]-SUM(Table110[[#This Row],[Planned Maintenance]:[Start and Finish Production]]) -> 22 | AD4: 0.5 | AI4: =(Table110[[#This Row],[Hours Used]]-SUM(Table110[[#This Row],[Planned Maintenance]:[Start and Finish Production]])-SUM(Table110[[#This Row],[Minor Stoppages]:[Material Shortages]])-Table110[[#This Row],[Quality Loss (Hrs)]]-Table110[[#This Row],[Operating Time]])/3 -> 0.06462585 | AJ4: =IFERROR(IF(Table110[[#This Row],[SKU]]="",0,Table110[[#This Row],[Quality Loss (T)]]/(Table110[[#This Row],[SOC (TPD)]]/24)),"") -> 0 | AK4: =IFERROR(IF(Table110[[#This Row],[SKU]]="",0,Table110[[#This Row],[Volume Delivered (T)]]/(Table110[[#This Row],[SOC (TPD)]]/24)),"") -> 21.306122 | AL4: =IFERROR(Table110[[#This Row],[Operating Time]]/Table110[[#This Row],[PRODUCTION HOURS]],"") -> 0.96846011 | AN4: NO | AO4: NO | AP4: 0 | AQ4: 0 | AS4: =IFERROR(SUMIFS(#REF!,#REF!,'Shift Wise-Data Sheet'!A:A,#REF!,"Samridhi Perk Line")/SUMIFS(#REF!,#REF!,'Shift Wise-Data Sheet'!A:A,#REF!,"Samridhi Perk Line"),"") | AU4: 0 | AV4: =IFERROR(VLOOKUP(Table110[[#This Row],[Date]],'Overweight Data'!A2:G1097,6,FALSE),"") | AW4: =IFERROR( IF( OR(Table110[[#This Row],[Operating Time]]=0, (Table110[[#This Row],[Operating Time]]/IF(AD4<=1,AD4+1,AD4))*60=0), 1, ((Table110[[#This Row],[Operating Time]])/IF(AD4<=1,AD4+1,AD4))*60 ), "_") -> 852.2449 | AX4: =COUNTIFS('Downtime Data'!A:A,Table110[[#This Row],[Date]]) -> 1 | AY4: =IFERROR((SUM(Table110[[#This Row],[Minor Stoppages]:[Material Shortages]])/Table110[[#This Row],['# Stops]])*60,"") -> 30 | BA4: 46048 | BE4: =21*7 -> 147
A5: 46022 | B5: =IF(A5="","",TEXT(A5,"dddddd")) -> Wednesday | D5: _10.3GM | E5: {=IFERROR(INDIRECT(D5),"")} -> 39.2 | F5: 32 | G5: 38.3 | H5: =IFERROR((Table110[[#This Row],[Plan]]/Table110[[#This Row],[Hours Used]])/(Table110[[#This Row],[SOC (TPD)]]/24),"") -> 0.81632653 | I5: =IFERROR((Table110[[#This Row],[Volume Delivered (T)]]/Table110[[#This Row],[Hours Used]])/(Table110[[#This Row],[SOC (TPD)]]/24),"") -> 0.97704082 | N5: 0.035 | R5: 1 | S5: 1 | T5: =IF(Table110[[#This Row],[SKU]]="",0,24-Table110[[#This Row],[Legal Non-Operating Time]]-Table110[[#This Row],[No Demand Time]]-Table110[[#This Row],[Force Majeure]]) -> 24 | AB5: =Table110[[#This Row],[Hours Used]]-SUM(Table110[[#This Row],[Planned Maintenance]:[Start and Finish Production]]) -> 24 | AI5: =(Table110[[#This Row],[Hours Used]]-SUM(Table110[[#This Row],[Planned Maintenance]:[Start and Finish Production]])-SUM(Table110[[#This Row],[Minor Stoppages]:[Material Shortages]])-Table110[[#This Row],[Quality Loss (Hrs)]]-Table110[[#This Row],[Operating Time]])/3 -> 0.18367347 | AJ5: =IFERROR(IF(Table110[[#This Row],[SKU]]="",0,Table110[[#This Row],[Quality Loss (T)]]/(Table110[[#This Row],[SOC (TPD)]]/24)),"") -> 0 | AK5: =IFERROR(IF(Table110[[#This Row],[SKU]]="",0,Table110[[#This Row],[Volume Delivered (T)]]/(Table110[[#This Row],[SOC (TPD)]]/24)),"") -> 23.44898 | AL5: =IFERROR(Table110[[#This Row],[Operating Time]]/Table110[[#This Row],[PRODUCTION HOURS]],"") -> 0.97704082 | AN5: NO | AO5: NO | AP5: 0 | AQ5: 0 | AS5: =IFERROR(SUMIFS(#REF!,#REF!,'Shift Wise-Data Sheet'!A:A,#REF!,"Samridhi Perk Line")/SUMIFS(#REF!,#REF!,'Shift Wise-Data Sheet'!A:A,#REF!,"Samridhi Perk Line"),"") | AU5: 0 | AV5: =IFERROR(VLOOKUP(Table110[[#This Row],[Date]],'Overweight Data'!A3:G1098,6,FALSE),"") | AW5: =IFERROR( IF( OR(Table110[[#This Row],[Operating Time]]=0, (Table110[[#This Row],[Operating Time]]/IF(AD5<=1,AD5+1,AD5))*60=0), 1, ((Table110[[#This Row],[Operating Time]])/IF(AD5<=1,AD5+1,AD5))*60 ), "_") -> 1406.9388 | AX5: =COUNTIFS('Downtime Data'!A:A,Table110[[#This Row],[Date]]) -> 0 | AY5: =IFERROR((SUM(Table110[[#This Row],[Minor Stoppages]:[Material Shortages]])/Table110[[#This Row],['# Stops]])*60,"") | BA5: 46048
A6: 46023 | B6: =IF(A6="","",TEXT(A6,"dddddd")) -> Thursday | D6: _10.3GM | E6: {=IFERROR(INDIRECT(D6),"")} -> 39.2 | F6: 27.5 | G6: 35.5 | H6: =IFERROR((Table110[[#This Row],[Plan]]/Table110[[#This Row],[Hours Used]])/(Table110[[#This Row],[SOC (TPD)]]/24),"") -> 0.70153061 | I6: =IFERROR((Table110[[#This Row],[Volume Delivered (T)]]/Table110[[#This Row],[Hours Used]])/(Table110[[#This Row],[SOC (TPD)]]/24),"") -> 0.90561224 | M6: 1.756 | N6: 0.035 | R6: 0 | S6: 0 | T6: =IF(Table110[[#This Row],[SKU]]="",0,24-Table110[[#This Row],[Legal Non-Operating Time]]-Table110[[#This Row],[No Demand Time]]-Table110[[#This Row],[Force Majeure]]) -> 24 | X6: 1 | AB6: =Table110[[#This Row],[Hours Used]]-SUM(Table110[[#This Row],[Planned Maintenance]:[Start and Finish Production]]) -> 23 | AI6: =(Table110[[#This Row],[Hours Used]]-SUM(Table110[[#This Row],[Planned Maintenance]:[Start and Finish Production]])-SUM(Table110[[#This Row],[Minor Stoppages]:[Material Shortages]])-Table110[[#This Row],[Quality Loss (Hrs)]]-Table110[[#This Row],[Operating Time]])/3 -> 0.063401361 | AJ6: =IFERROR(IF(Table110[[#This Row],[SKU]]="",0,Table110[[#This Row],[Quality Loss (T)]]/(Table110[[#This Row],[SOC (TPD)]]/24)),"") -> 1.075102 | AK6: =IFERROR(IF(Table110[[#This Row],[SKU]]="",0,Table110[[#This Row],[Volume Delivered (T)]]/(Table110[[#This Row],[SOC (TPD)]]/24)),"") -> 21.734694 | AL6: =IFERROR(Table110[[#This Row],[Operating Time]]/Table110[[#This Row],[PRODUCTION HOURS]],"") -> 0.94498669 | AM6: 96 | AN6: YES | AO6: NO | AP6: 23 | AQ6: 23 | AS6: =IFERROR(SUMIFS(#REF!,#REF!,'Shift Wise-Data Sheet'!A:A,#REF!,"Samridhi Perk Line")/SUMIFS(#REF!,#REF!,'Shift Wise-Data Sheet'!A:A,#REF!,"Samridhi Perk Line"),"") | AT6: 13 | AU6: 0 | AV6: =IFERROR(VLOOKUP(Table110[[#This Row],[Date]],'Overweight Data'!A4:G1099,6,FALSE),"") | AW6: =IFERROR( IF( OR(Table110[[#This Row],[Operating Time]]=0, (Table110[[#This Row],[Operating Time]]/IF(AD6<=1,AD6+1,AD6))*60=0), 1, ((Table110[[#This Row],[Operating Time]])/IF(AD6<=1,AD6+1,AD6))*60 ), "_") -> 1304.0816 | AX6: =COUNTIFS('Downtime Data'!A:A,Table110[[#This Row],[Date]]) -> 1 | AY6: =IFERROR((SUM(Table110[[#This Row],[Minor Stoppages]:[Material Shortages]])/Table110[[#This Row],['# Stops]])*60,"") -> 0 | BA6: 46048
A7: 46024 | B7: =IF(A7="","",TEXT(A7,"dddddd")) -> Friday | D7: _10.3GM | E7: {=IFERROR(INDIRECT(D7),"")} -> 39.2 | F7: 33.5 | G7: 35.1 | H7: =IFERROR((Table110[[#This Row],[Plan]]/Table110[[#This Row],[Hours Used]])/(Table110[[#This Row],[SOC (TPD)]]/24),"") -> 0.85459184 | I7: =IFERROR((Table110[[#This Row],[Volume Delivered (T)]]/Table110[[#This Row],[Hours Used]])/(Table110[[#This Row],[SOC (TPD)]]/24),"") -> 0.89540816 | M7: 1.386 | N7: 0.035 | R7: 1 | S7: 1 | T7: =IF(Table110[[#This Row],[SKU]]="",0,24-Table110[[#This Row],[Legal Non-Operating Time]]-Table110[[#This Row],[No Demand Time]]-Table110[[#This Row],[Force Majeure]]) -> 24 | V7: 1 | AB7: =Table110[[#This Row],[Hours Used]]-SUM(Table110[[#This Row],[Planned Maintenance]:[Start and Finish Production]]) -> 23 | AC7: 0.18333333 | AE7: 0.25 | AI7: =(Table110[[#This Row],[Hours Used]]-SUM(Table110[[#This Row],[Planned Maintenance]:[Start and Finish Production]])-SUM(Table110[[#This Row],[Minor Stoppages]:[Material Shortages]])-Table110[[#This Row],[Quality Loss (Hrs)]]-Table110[[#This Row],[Operating Time]])/3 -> 0.076099773 | AJ7: =IFERROR(IF(Table110[[#This Row],[SKU]]="",0,Table110[[#This Row],[Quality Loss (T)]]/(Table110[[#This Row],[SOC (TPD)]]/24)),"") -> 0.84857143 | AK7: =IFERROR(IF(Table110[[#This Row],[SKU]]="",0,Table110[[#This Row],[Volume Delivered (T)]]/(Table110[[#This Row],[SOC (TPD)]]/24)),"") -> 21.489796 | AL7: =IFERROR(Table110[[#This Row],[Operating Time]]/Table110[[#This Row],[PRODUCTION HOURS]],"") -> 0.93433895 | AM7: 89 | AN7: YES | AO7: NO | AP7: 26 | AQ7: 26 | AR7: 1 | AS7: =IFERROR(SUMIFS(#REF!,#REF!,'Shift Wise-Data Sheet'!A:A,#REF!,"Samridhi Perk Line")/SUMIFS(#REF!,#REF!,'Shift Wise-Data Sheet'!A:A,#REF!,"Samridhi Perk Line"),"") | AT7: 4 | AU7: 0 | AV7: =IFERROR(VLOOKUP(Table110[[#This Row],[Date]],'Overweight Data'!A5:G1100,6,FALSE),"") -> 0.02887921 | AW7: =IFERROR( IF( OR(Table110[[#This Row],[Operating Time]]=0, (Table110[[#This Row],[Operating Time]]/IF(AD7<=1,AD7+1,AD7))*60=0), 1, ((Table110[[#This Row],[Operating Time]])/IF(AD7<=1,AD7+1,AD7))*60 ), "_") -> 1289.3878 | AX7: =COUNTIFS('Downtime Data'!A:A,Table110[[#This Row],[Date]]) -> 2 | AY7: =IFERROR((SUM(Table110[[#This Row],[Minor Stoppages]:[Material Shortages]])/Table110[[#This Row],['# Stops]])*60,"") -> 13 | BA7: 46048
A8: 46025 | B8: =IF(A8="","",TEXT(A8,"dddddd")) -> Saturday | D8: _10.3GM | E8: {=IFERROR(INDIRECT(D8),"")} -> 39.2 | F8: 33.5 | G8: 35.1 | H8: =IFERROR((Table110[[#This Row],[Plan]]/Table110[[#This Row],[Hours Used]])/(Table110[[#This Row],[SOC (TPD)]]/24),"") -> 0.85459184 | I8: =IFERROR((Table110[[#This Row],[Volume Delivered (T)]]/Table110[[#This Row],[Hours Used]])/(Table110[[#This Row],[SOC (TPD)]]/24),"") -> 0.89540816 | M8: 2.038 | N8: 0.035 | R8: 0 | S8: 0 | T8: =IF(Table110[[#This Row],[SKU]]="",0,24-Table110[[#This Row],[Legal Non-Operating Time]]-Table110[[#This Row],[No Demand Time]]-Table110[[#This Row],[Force Majeure]]) -> 24 | AB8: =Table110[[#This Row],[Hours Used]]-SUM(Table110[[#This Row],[Planned Maintenance]:[Start and Finish Production]]) -> 24 | AC8: 0.3 | AD8: 0.29166667 | AE8: 0.25 | AI8: =(Table110[[#This Row],[Hours Used]]-SUM(Table110[[#This Row],[Planned Maintenance]:[Start and Finish Production]])-SUM(Table110[[#This Row],[Minor Stoppages]:[Material Shortages]])-Table110[[#This Row],[Quality Loss (Hrs)]]-Table110[[#This Row],[Operating Time]])/3 -> 0.14026077 | AJ8: =IFERROR(IF(Table110[[#This Row],[SKU]]="",0,Table110[[#This Row],[Quality Loss (T)]]/(Table110[[#This Row],[SOC (TPD)]]/24)),"") -> 1.2477551 | AK8: =IFERROR(IF(Table110[[#This Row],[SKU]]="",0,Table110[[#This Row],[Volume Delivered (T)]]/(Table110[[#This Row],[SOC (TPD)]]/24)),"") -> 21.489796 | AL8: =IFERROR(Table110[[#This Row],[Operating Time]]/Table110[[#This Row],[PRODUCTION HOURS]],"") -> 0.89540816 | AM8: 103 | AN8: NO | AO8: NO | AP8: 0 | AQ8: 0 | AS8: =IFERROR(SUMIFS(#REF!,#REF!,'Shift Wise-Data Sheet'!A:A,#REF!,"Samridhi Perk Line")/SUMIFS(#REF!,#REF!,'Shift Wise-Data Sheet'!A:A,#REF!,"Samridhi Perk Line"),"") | AT8: 2 | AU8: 0 | AV8: =IFERROR(VLOOKUP(Table110[[#This Row],[Date]],'Overweight Data'!A6:G1101,6,FALSE),"") -> 0.036184669 | AW8: =IFERROR( IF( OR(Table110[[#This Row],[Operating Time]]=0, (Table110[[#This Row],[Operating Time]]/IF(AD8<=1,AD8+1,AD8))*60=0), 1, ((Table110[[#This Row],[Operating Time]])/IF(AD8<=1,AD8+1,AD8))*60 ), "_") -> 998.23568 | AX8: =COUNTIFS('Downtime Data'!A:A,Table110[[#This Row],[Date]]) -> 3 | AY8: =IFERROR((SUM(Table110[[#This Row],[Minor Stoppages]:[Material Shortages]])/Table110[[#This Row],['# Stops]])*60,"") -> 16.833333 | BA8: 46048
A9: 46026 | B9: =IF(A9="","",TEXT(A9,"dddddd")) -> Sunday | D9: _10.3GM | E9: {=IFERROR(INDIRECT(D9),"")} -> 39.2 | F9: 33.5 | G9: 38.1 | H9: =IFERROR((Table110[[#This Row],[Plan]]/Table110[[#This Row],[Hours Used]])/(Table110[[#This Row],[SOC (TPD)]]/24),"") -> 0.85459184 | I9: =IFERROR((Table110[[#This Row],[Volume Delivered (T)]]/Table110[[#This Row],[Hours Used]])/(Table110[[#This Row],[SOC (TPD)]]/24),"") -> 0.97193878 | M9: 0.5 | N9: 0.035 | R9: 0 | S9: 0 | T9: =IF(Table110[[#This Row],[SKU]]="",0,24-Table110[[#This Row],[Legal Non-Operating Time]]-Table110[[#This Row],[No Demand Time]]-Table110[[#This Row],[Force Majeure]]) -> 24 | AB9: =Table110[[#This Row],[Hours Used]]-SUM(Table110[[#This Row],[Planned Maintenance]:[Start and Finish Production]]) -> 24 | AI9: =(Table110[[#This Row],[Hours Used]]-SUM(Table110[[#This Row],[Planned Maintenance]:[Start and Finish Production]])-SUM(Table110[[#This Row],[Minor Stoppages]:[Material Shortages]])-Table110[[#This Row],[Quality Loss (Hrs)]]-Table110[[#This Row],[Operating Time]])/3 -> 0.12244898 | AJ9: =IFERROR(IF(Table110[[#This Row],[SKU]]="",0,Table110[[#This Row],[Quality Loss (T)]]/(Table110[[#This Row],[SOC (TPD)]]/24)),"") -> 0.30612245 | AK9: =IFERROR(IF(Table110[[#This Row],[SKU]]="",0,Table110[[#This Row],[Volume Delivered (T)]]/(Table110[[#This Row],[SOC (TPD)]]/24)),"") -> 23.326531 | AL9: =IFERROR(Table110[[#This Row],[Operating Time]]/Table110[[#This Row],[PRODUCTION HOURS]],"") -> 0.97193878 | AM9: 110 | AN9: YES | AO9: YES | AP9: 0 | AQ9: 0 | AS9: =IFERROR(SUMIFS(#REF!,#REF!,'Shift Wise-Data Sheet'!A:A,#REF!,"Samridhi Perk Line")/SUMIFS(#REF!,#REF!,'Shift Wise-Data Sheet'!A:A,#REF!,"Samridhi Perk Line"),"") | AT9: 10 | AU9: 0 | AV9: =IFERROR(VLOOKUP(Table110[[#This Row],[Date]],'Overweight Data'!A7:G1102,6,FALSE),"") -> 0.027462253 | AW9: =IFERROR( IF( OR(Table110[[#This Row],[Operating Time]]=0, (Table110[[#This Row],[Operating Time]]/IF(AD9<=1,AD9+1,AD9))*60=0), 1, ((Table110[[#This Row],[Operating Time]])/IF(AD9<=1,AD9+1,AD9))*60 ), "_") -> 1399.5918 | AX9: =COUNTIFS('Downtime Data'!A:A,Table110[[#This Row],[Date]]) -> 0 | AY9: =IFERROR((SUM(Table110[[#This Row],[Minor Stoppages]:[Material Shortages]])/Table110[[#This Row],['# Stops]])*60,"") | BA9: 46048
A10: 46027 | B10: =IF(A10="","",TEXT(A10,"dddddd")) -> Monday | D10: _10.3GM_HT | E10: {=IFERROR(INDIRECT(D10),"")} -> 34.2 | F10: 29.5 | G10: 29.740487 | H10: =IFERROR((Table110[[#This Row],[Plan]]/Table110[[#This Row],[Hours Used]])/(Table110[[#This Row],[SOC (TPD)]]/24),"") -> 0.8625731 | I10: =IFERROR((Table110[[#This Row],[Volume Delivered (T)]]/Table110[[#This Row],[Hours Used]])/(Table110[[#This Row],[SOC (TPD)]]/24),"") -> 0.86960488 | M10: 1.367 | N10: 0.065 | R10: 0 | S10: 0 | T10: =IF(Table110[[#This Row],[SKU]]="",0,24-Table110[[#This Row],[Legal Non-Operating Time]]-Table110[[#This Row],[No Demand Time]]-Table110[[#This Row],[Force Majeure]]) -> 24 | X10: 2 | AB10: =Table110[[#This Row],[Hours Used]]-SUM(Table110[[#This Row],[Planned Maintenance]:[Start and Finish Production]]) -> 22 | AE10: 0.2 | AI10: =(Table110[[#This Row],[Hours Used]]-SUM(Table110[[#This Row],[Planned Maintenance]:[Start and Finish Production]])-SUM(Table110[[#This Row],[Minor Stoppages]:[Material Shortages]])-Table110[[#This Row],[Quality Loss (Hrs)]]-Table110[[#This Row],[Operating Time]])/3 -> -0.0099384795 | AJ10: =IFERROR(IF(Table110[[#This Row],[SKU]]="",0,Table110[[#This Row],[Quality Loss (T)]]/(Table110[[#This Row],[SOC (TPD)]]/24)),"") -> 0.95929825 | AK10: =IFERROR(IF(Table110[[#This Row],[SKU]]="",0,Table110[[#This Row],[Volume Delivered (T)]]/(Table110[[#This Row],[SOC (TPD)]]/24)),"") -> 20.870517 | AL10: =IFERROR(Table110[[#This Row],[Operating Time]]/Table110[[#This Row],[PRODUCTION HOURS]],"") -> 0.94865987 | AM10: 107 | AN10: YES | AO10: YES | AP10: 0 | AQ10: 0 | AS10: =IFERROR(SUMIFS(#REF!,#REF!,'Shift Wise-Data Sheet'!A:A,#REF!,"Samridhi Perk Line")/SUMIFS(#REF!,#REF!,'Shift Wise-Data Sheet'!A:A,#REF!,"Samridhi Perk Line"),"") | AT10: 20 | AU10: 0 | AV10: =IFERROR(VLOOKUP(Table110[[#This Row],[Date]],'Overweight Data'!A8:G1103,6,FALSE),"") -> 0.022648084 | AW10: =IFERROR( IF( OR(Table110[[#This Row],[Operating Time]]=0, (Table110[[#This Row],[Operating Time]]/IF(AD10<=1,AD10+1,AD10))*60=0), 1, ((Table110[[#This Row],[Operating Time]])/IF(AD10<=1,AD10+1,AD10))*60 ), "_") -> 1252.231 | AX10: =COUNTIFS('Downtime Data'!A:A,Table110[[#This Row],[Date]]) -> 2 | AY10: =IFERROR((SUM(Table110[[#This Row],[Minor Stoppages]:[Material Shortages]])/Table110[[#This Row],['# Stops]])*60,"") -> 6 | BA10: 46048
A11: 46028 | B11: =IF(A11="","",TEXT(A11,"dddddd")) -> Tuesday | D11: _10.3GM_HT | E11: {=IFERROR(INDIRECT(D11),"")} -> 34.2 | F11: 30 | G11: 29.884616 | H11: =IFERROR((Table110[[#This Row],[Plan]]/Table110[[#This Row],[Hours Used]])/(Table110[[#This Row],[SOC (TPD)]]/24),"") -> 0.87719298 | I11: =IFERROR((Table110[[#This Row],[Volume Delivered (T)]]/Table110[[#This Row],[Hours Used]])/(Table110[[#This Row],[SOC (TPD)]]/24),"") -> 0.87381918 | N11: 0.062 | R11: 15 | S11: 15 | T11: =IF(Table110[[#This Row],[SKU]]="",0,24-Table110[[#This Row],[Legal Non-Operating Time]]-Table110[[#This Row],[No Demand Time]]-Table110[[#This Row],[Force Majeure]]) -> 24 | U11: 1.8 | X11: 1.5 | AB11: =Table110[[#This Row],[Hours Used]]-SUM(Table110[[#This Row],[Planned Maintenance]:[Start and Finish Production]]) -> 20.7 | AI11: =(Table110[[#This Row],[Hours Used]]-SUM(Table110[[#This Row],[Planned Maintenance]:[Start and Finish Production]])-SUM(Table110[[#This Row],[Minor Stoppages]:[Material Shortages]])-Table110[[#This Row],[Quality Loss (Hrs)]]-Table110[[#This Row],[Operating Time]])/3 -> -0.09055345 | AJ11: =IFERROR(IF(Table110[[#This Row],[SKU]]="",0,Table110[[#This Row],[Quality Loss (T)]]/(Table110[[#This Row],[SOC (TPD)]]/24)),"") -> 0 | AK11: =IFERROR(IF(Table110[[#This Row],[SKU]]="",0,Table110[[#This Row],[Volume Delivered (T)]]/(Table110[[#This Row],[SOC (TPD)]]/24)),"") -> 20.97166 | AL11: =IFERROR(Table110[[#This Row],[Operating Time]]/Table110[[#This Row],[PRODUCTION HOURS]],"") -> 1.0131237 | AM11: 130 | AN11: YES | AO11: YES | AP11: 60 | AQ11: 60 | AR11: 13 | AS11: =IFERROR(SUMIFS(#REF!,#REF!,'Shift Wise-Data Sheet'!A:A,#REF!,"Samridhi Perk Line")/SUMIFS(#REF!,#REF!,'Shift Wise-Data Sheet'!A:A,#REF!,"Samridhi Perk Line"),"") | AT11: 47 | AU11: 0 | AV11: =IFERROR(VLOOKUP(Table110[[#This Row],[Date]],'Overweight Data'!A9:G1104,6,FALSE),"") -> 0.018388357 | AW11: =IFERROR( IF( OR(Table110[[#This Row],[Operating Time]]=0, (Table110[[#This Row],[Operating Time]]/IF(AD11<=1,AD11+1,AD11))*60=0), 1, ((Table110[[#This Row],[Operating Time]])/IF(AD11<=1,AD11+1,AD11))*60 ), "_") -> 1258.2996 | AX11: =COUNTIFS('Downtime Data'!A:A,Table110[[#This Row],[Date]]) -> 1 | AY11: =IFERROR((SUM(Table110[[#This Row],[Minor Stoppages]:[Material Shortages]])/Table110[[#This Row],['# Stops]])*60,"") -> 0 | BA11: 46048
A12: 46029 | B12: =IF(A12="","",TEXT(A12,"dddddd")) -> Wednesday | D12: _10.3GM_HT | E12: {=IFERROR(INDIRECT(D12),"")} -> 34.2 | F12: 30 | G12: 28.848798 | H12: =IFERROR((Table110[[#This Row],[Plan]]/Table110[[#This Row],[Hours Used]])/(Table110[[#This Row],[SOC (TPD)]]/24),"") -> 0.87719298 | I12: =IFERROR((Table110[[#This Row],[Volume Delivered (T)]]/Table110[[#This Row],[Hours Used]])/(Table110[[#This Row],[SOC (TPD)]]/24),"") -> 0.84353211 | M12: 1.609 | N12: 0.055 | R12: 15 | S12: 15 | T12: =IF(Table110[[#This Row],[SKU]]="",0,24-Table110[[#This Row],[Legal Non-Operating Time]]-Table110[[#This Row],[No Demand Time]]-Table110[[#This Row],[Force Majeure]]) -> 24 | U12: 1 | AB12: =Table110[[#This Row],[Hours Used]]-SUM(Table110[[#This Row],[Planned Maintenance]:[Start and Finish Production]]) -> 23 | AE12: 1.5 | AI12: =(Table110[[#This Row],[Hours Used]]-SUM(Table110[[#This Row],[Planned Maintenance]:[Start and Finish Production]])-SUM(Table110[[#This Row],[Minor Stoppages]:[Material Shortages]])-Table110[[#This Row],[Quality Loss (Hrs)]]-Table110[[#This Row],[Operating Time]])/3 -> 0.042035556 | AJ12: =IFERROR(IF(Table110[[#This Row],[SKU]]="",0,Table110[[#This Row],[Quality Loss (T)]]/(Table110[[#This Row],[SOC (TPD)]]/24)),"") -> 1.1291228 | AK12: =IFERROR(IF(Table110[[#This Row],[SKU]]="",0,Table110[[#This Row],[Volume Delivered (T)]]/(Table110[[#This Row],[SOC (TPD)]]/24)),"") -> 20.244771 | AL12: =IFERROR(Table110[[#This Row],[Operating Time]]/Table110[[#This Row],[PRODUCTION HOURS]],"") -> 0.88020741 | AM12: 120 | AN12: YES | AO12: YES | AP12: 0 | AQ12: 0 | AR12: 13 | AS12: =IFERROR(SUMIFS(#REF!,#REF!,'Shift Wise-Data Sheet'!A:A,#REF!,"Samridhi Perk Line")/SUMIFS(#REF!,#REF!,'Shift Wise-Data Sheet'!A:A,#REF!,"Samridhi Perk Line"),"") | AT12: 15 | AU12: 0 | AV12: =IFERROR(VLOOKUP(Table110[[#This Row],[Date]],'Overweight Data'!A10:G1105,6,FALSE),"") -> 0.01786372 | AW12: =IFERROR( IF( OR(Table110[[#This Row],[Operating Time]]=0, (Table110[[#This Row],[Operating Time]]/IF(AD12<=1,AD12+1,AD12))*60=0), 1, ((Table110[[#This Row],[Operating Time]])/IF(AD12<=1,AD12+1,AD12))*60 ), "_") -> 1214.6862 | AX12: =COUNTIFS('Downtime Data'!A:A,Table110[[#This Row],[Date]]) -> 1 | AY12: =IFERROR((SUM(Table110[[#This Row],[Minor Stoppages]:[Material Shortages]])/Table110[[#This Row],['# Stops]])*60,"") -> 90 | BA12: 46048
A13: 46030 | B13: =IF(A13="","",TEXT(A13,"dddddd")) -> Thursday | D13: _10.3GM_HT | E13: {=IFERROR(INDIRECT(D13),"")} -> 34.2 | F13: 30 | G13: 32.847984 | H13: =IFERROR((Table110[[#This Row],[Plan]]/Table110[[#This Row],[Hours Used]])/(Table110[[#This Row],[SOC (TPD)]]/24),"") -> 0.87719298 | I13: =IFERROR((Table110[[#This Row],[Volume Delivered (T)]]/Table110[[#This Row],[Hours Used]])/(Table110[[#This Row],[SOC (TPD)]]/24),"") -> 0.96046737 | M13: 1.2 | N13: 0.052 | R13: 4 | S13: 4 | T13: =IF(Table110[[#This Row],[SKU]]="",0,24-Table110[[#This Row],[Legal Non-Operating Time]]-Table110[[#This Row],[No Demand Time]]-Table110[[#This Row],[Force Majeure]]) -> 24 | AB13: =Table110[[#This Row],[Hours Used]]-SUM(Table110[[#This Row],[Planned Maintenance]:[Start and Finish Production]]) -> 24 | AI13: =(Table110[[#This Row],[Hours Used]]-SUM(Table110[[#This Row],[Planned Maintenance]:[Start and Finish Production]])-SUM(Table110[[#This Row],[Minor Stoppages]:[Material Shortages]])-Table110[[#This Row],[Quality Loss (Hrs)]]-Table110[[#This Row],[Operating Time]])/3 -> 0.035559298 | AJ13: =IFERROR(IF(Table110[[#This Row],[SKU]]="",0,Table110[[#This Row],[Quality Loss (T)]]/(Table110[[#This Row],[SOC (TPD)]]/24)),"") -> 0.84210526 | AK13: =IFERROR(IF(Table110[[#This Row],[SKU]]="",0,Table110[[#This Row],[Volume Delivered (T)]]/(Table110[[#This Row],[SOC (TPD)]]/24)),"") -> 23.051217 | AL13: =IFERROR(Table110[[#This Row],[Operating Time]]/Table110[[#This Row],[PRODUCTION HOURS]],"") -> 0.96046737 | AM13: 132 | AN13: YES | AO13: YES | AP13: 0 | AQ13: 0 | AR13: 3 | AS13: =IFERROR(SUMIFS(#REF!,#REF!,'Shift Wise-Data Sheet'!A:A,#REF!,"Samridhi Perk Line")/SUMIFS(#REF!,#REF!,'Shift Wise-Data Sheet'!A:A,#REF!,"Samridhi Perk Line"),"") | AT13: 25 | AU13: 0 | AV13: =IFERROR(VLOOKUP(Table110[[#This Row],[Date]],'Overweight Data'!A11:G1106,6,FALSE),"") -> 0.025497238 | AW13: =IFERROR( IF( OR(Table110[[#This Row],[Operating Time]]=0, (Table110[[#This Row],[Operating Time]]/IF(AD13<=1,AD13+1,AD13))*60=0), 1, ((Table110[[#This Row],[Operating Time]])/IF(AD13<=1,AD13+1,AD13))*60 ), "_") -> 1383.073 | AX13: =COUNTIFS('Downtime Data'!A:A,Table110[[#This Row],[Date]]) -> 0 | AY13: =IFERROR((SUM(Table110[[#This Row],[Minor Stoppages]:[Material Shortages]])/Table110[[#This Row],['# Stops]])*60,"") | BA13: 46048
A14: 46031 | B14: =IF(A14="","",TEXT(A14,"dddddd")) -> Friday | D14: _10.3GM_HT | E14: {=IFERROR(INDIRECT(D14),"")} -> 34.2 | F14: 30 | G14: 24.2 | H14: =IFERROR((Table110[[#This Row],[Plan]]/Table110[[#This Row],[Hours Used]])/(Table110[[#This Row],[SOC (TPD)]]/24),"") -> 0.87719298 | I14: =IFERROR((Table110[[#This Row],[Volume Delivered (T)]]/Table110[[#This Row],[Hours Used]])/(Table110[[#This Row],[SOC (TPD)]]/24),"") -> 0.70760234 | M14: 1.363 | N14: 0.047 | R14: 0 | S14: 0 | T14: =IF(Table110[[#This Row],[SKU]]="",0,24-Table110[[#This Row],[Legal Non-Operating Time]]-Table110[[#This Row],[No Demand Time]]-Table110[[#This Row],[Force Majeure]]) -> 24 | AB14: =Table110[[#This Row],[Hours Used]]-SUM(Table110[[#This Row],[Planned Maintenance]:[Start and Finish Production]]) -> 24 | AD14: 6 | AI14: =(Table110[[#This Row],[Hours Used]]-SUM(Table110[[#This Row],[Planned Maintenance]:[Start and Finish Production]])-SUM(Table110[[#This Row],[Minor Stoppages]:[Material Shortages]])-Table110[[#This Row],[Quality Loss (Hrs)]]-Table110[[#This Row],[Operating Time]])/3 -> 0.020350877 | AJ14: =IFERROR(IF(Table110[[#This Row],[SKU]]="",0,Table110[[#This Row],[Quality Loss (T)]]/(Table110[[#This Row],[SOC (TPD)]]/24)),"") -> 0.95649123 | AK14: =IFERROR(IF(Table110[[#This Row],[SKU]]="",0,Table110[[#This Row],[Volume Delivered (T)]]/(Table110[[#This Row],[SOC (TPD)]]/24)),"") -> 16.982456 | AL14: =IFERROR(Table110[[#This Row],[Operating Time]]/Table110[[#This Row],[PRODUCTION HOURS]],"") -> 0.70760234 | AN14: YES | AO14: YES | AP14: 0 | AQ14: 0 | AS14: =IFERROR(SUMIFS(#REF!,#REF!,'Shift Wise-Data Sheet'!A:A,#REF!,"Samridhi Perk Line")/SUMIFS(#REF!,#REF!,'Shift Wise-Data Sheet'!A:A,#REF!,"Samridhi Perk Line"),"") | AT14: 12 | AU14: 0 | AV14: =IFERROR(VLOOKUP(Table110[[#This Row],[Date]],'Overweight Data'!A12:G1107,6,FALSE),"") -> 0.027108656 | AW14: =IFERROR( IF( OR(Table110[[#This Row],[Operating Time]]=0, (Table110[[#This Row],[Operating Time]]/IF(AD14<=1,AD14+1,AD14))*60=0), 1, ((Table110[[#This Row],[Operating Time]])/IF(AD14<=1,AD14+1,AD14))*60 ), "_") -> 169.82456 | AX14: =COUNTIFS('Downtime Data'!A:A,Table110[[#This Row],[Date]]) -> 1 | AY14: =IFERROR((SUM(Table110[[#This Row],[Minor Stoppages]:[Material Shortages]])/Table110[[#This Row],['# Stops]])*60,"") -> 360 | BA14: 46048
A15: 46032 | B15: =IF(A15="","",TEXT(A15,"dddddd")) -> Saturday | D15: _10.3GM_HT | E15: {=IFERROR(INDIRECT(D15),"")} -> 34.2 | F15: 15 | G15: 17 | H15: =IFERROR((Table110[[#This Row],[Plan]]/Table110[[#This Row],[Hours Used]])/(Table110[[#This Row],[SOC (TPD)]]/24),"") -> 0.43859649 | I15: =IFERROR((Table110[[#This Row],[Volume Delivered (T)]]/Table110[[#This Row],[Hours Used]])/(Table110[[#This Row],[SOC (TPD)]]/24),"") -> 0.49707602 | N15: 0.042 | R15: 0 | S15: 0 | T15: =IF(Table110[[#This Row],[SKU]]="",0,24-Table110[[#This Row],[Legal Non-Operating Time]]-Table110[[#This Row],[No Demand Time]]-Table110[[#This Row],[Force Majeure]]) -> 24 | W15: 12 | AB15: =Table110[[#This Row],[Hours Used]]-SUM(Table110[[#This Row],[Planned Maintenance]:[Start and Finish Production]]) -> 12 | AI15: =(Table110[[#This Row],[Hours Used]]-SUM(Table110[[#This Row],[Planned Maintenance]:[Start and Finish Production]])-SUM(Table110[[#This Row],[Minor Stoppages]:[Material Shortages]])-Table110[[#This Row],[Quality Loss (Hrs)]]-Table110[[#This Row],[Operating Time]])/3 -> 0.023391813 | AJ15: =IFERROR(IF(Table110[[#This Row],[SKU]]="",0,Table110[[#This Row],[Quality Loss (T)]]/(Table110[[#This Row],[SOC (TPD)]]/24)),"") -> 0 | AK15: =IFERROR(IF(Table110[[#This Row],[SKU]]="",0,Table110[[#This Row],[Volume Delivered (T)]]/(Table110[[#This Row],[SOC (TPD)]]/24)),"") -> 11.929825 | AL15: =IFERROR(Table110[[#This Row],[Operating Time]]/Table110[[#This Row],[PRODUCTION HOURS]],"") -> 0.99415205 | AM15: 131 | AN15: YES | AO15: YES | AP15: 0 | AQ15: 0 | AS15: =IFERROR(SUMIFS(#REF!,#REF!,'Shift Wise-Data Sheet'!A:A,#REF!,"Samridhi Perk Line")/SUMIFS(#REF!,#REF!,'Shift Wise-Data Sheet'!A:A,#REF!,"Samridhi Perk Line"),"") | AT15: 9 | AU15: 0 | AV15: =IFERROR(VLOOKUP(Table110[[#This Row],[Date]],'Overweight Data'!A13:G1108,6,FALSE),"") -> 0.031372007 | AW15: =IFERROR( IF( OR(Table110[[#This Row],[Operating Time]]=0, (Table110[[#This Row],[Operating Time]]/IF(AD15<=1,AD15+1,AD15))*60=0), 1, ((Table110[[#This Row],[Operating Time]])/IF(AD15<=1,AD15+1,AD15))*60 ), "_") -> 715.78947 | AX15: =COUNTIFS('Downtime Data'!A:A,Table110[[#This Row],[Date]]) -> 0 | AY15: =IFERROR((SUM(Table110[[#This Row],[Minor Stoppages]:[Material Shortages]])/Table110[[#This Row],['# Stops]])*60,"") | BA15: 46048
A16: 46033 | B16: =IF(A16="","",TEXT(A16,"dddddd")) -> Sunday | D16: _10.3GM_HT | E16: {=IFERROR(INDIRECT(D16),"")} -> 34.2 | F16: 30 | G16: 31.506096 | H16: =IFERROR((Table110[[#This Row],[Plan]]/Table110[[#This Row],[Hours Used]])/(Table110[[#This Row],[SOC (TPD)]]/24),"") -> 0.87719298 | I16: =IFERROR((Table110[[#This Row],[Volume Delivered (T)]]/Table110[[#This Row],[Hours Used]])/(Table110[[#This Row],[SOC (TPD)]]/24),"") -> 0.92123088 | M16: 1.603 | N16: 0.039 | R16: 1 | S16: 1 | T16: =IF(Table110[[#This Row],[SKU]]="",0,24-Table110[[#This Row],[Legal Non-Operating Time]]-Table110[[#This Row],[No Demand Time]]-Table110[[#This Row],[Force Majeure]]) -> 24 | AB16: =Table110[[#This Row],[Hours Used]]-SUM(Table110[[#This Row],[Planned Maintenance]:[Start and Finish Production]]) -> 24 | AD16: 0.60416667 | AI16: =(Table110[[#This Row],[Hours Used]]-SUM(Table110[[#This Row],[Planned Maintenance]:[Start and Finish Production]])-SUM(Table110[[#This Row],[Minor Stoppages]:[Material Shortages]])-Table110[[#This Row],[Quality Loss (Hrs)]]-Table110[[#This Row],[Operating Time]])/3 -> 0.053793333 | AJ16: =IFERROR(IF(Table110[[#This Row],[SKU]]="",0,Table110[[#This Row],[Quality Loss (T)]]/(Table110[[#This Row],[SOC (TPD)]]/24)),"") -> 1.1249123 | AK16: =IFERROR(IF(Table110[[#This Row],[SKU]]="",0,Table110[[#This Row],[Volume Delivered (T)]]/(Table110[[#This Row],[SOC (TPD)]]/24)),"") -> 22.109541 | AL16: =IFERROR(Table110[[#This Row],[Operating Time]]/Table110[[#This Row],[PRODUCTION HOURS]],"") -> 0.92123088 | AM16: 107 | AN16: YES | AO16: YES | AP16: 2 | AQ16: 0 | AR16: 1 | AS16: =IFERROR(SUMIFS(#REF!,#REF!,'Shift Wise-Data Sheet'!A:A,#REF!,"Samridhi Perk Line")/SUMIFS(#REF!,#REF!,'Shift Wise-Data Sheet'!A:A,#REF!,"Samridhi Perk Line"),"") | AT16: 4 | AU16: 0 | AV16: =IFERROR(VLOOKUP(Table110[[#This Row],[Date]],'Overweight Data'!A14:G1109,6,FALSE),"") -> 0.013554328 | AW16: =IFERROR( IF( OR(Table110[[#This Row],[Operating Time]]=0, (Table110[[#This Row],[Operating Time]]/IF(AD16<=1,AD16+1,AD16))*60=0), 1, ((Table110[[#This Row],[Operating Time]])/IF(AD16<=1,AD16+1,AD16))*60 ), "_") -> 826.95426 | AX16: =COUNTIFS('Downtime Data'!A:A,Table110[[#This Row],[Date]]) -> 1 | AY16: =IFERROR((SUM(Table110[[#This Row],[Minor Stoppages]:[Material Shortages]])/Table110[[#This Row],['# Stops]])*60,"") -> 36.25 | BA16: 46048
A17: 46034 | B17: =IF(A17="","",TEXT(A17,"dddddd")) -> Monday | D17: _10.3GM_HT | E17: {=IFERROR(INDIRECT(D17),"")} -> 34.2 | F17: 30 | G17: 28.5 | H17: =IFERROR((Table110[[#This Row],[Plan]]/Table110[[#This Row],[Hours Used]])/(Table110[[#This Row],[SOC (TPD)]]/24),"") -> 0.87719298 | I17: =IFERROR((Table110[[#This Row],[Volume Delivered (T)]]/Table110[[#This Row],[Hours Used]])/(Table110[[#This Row],[SOC (TPD)]]/24),"") -> 0.83333333 | N17: 0.036 | R17: 1 | S17: 1 | T17: =IF(Table110[[#This Row],[SKU]]="",0,24-Table110[[#This Row],[Legal Non-Operating Time]]-Table110[[#This Row],[No Demand Time]]-Table110[[#This Row],[Force Majeure]]) -> 24 | X17: 1.1 | AB17: =Table110[[#This Row],[Hours Used]]-SUM(Table110[[#This Row],[Planned Maintenance]:[Start and Finish Production]]) -> 22.9 | AD17: 3 | AI17: =(Table110[[#This Row],[Hours Used]]-SUM(Table110[[#This Row],[Planned Maintenance]:[Start and Finish Production]])-SUM(Table110[[#This Row],[Minor Stoppages]:[Material Shortages]])-Table110[[#This Row],[Quality Loss (Hrs)]]-Table110[[#This Row],[Operating Time]])/3 -> -0.033333333 | AJ17: =IFERROR(IF(Table110[[#This Row],[SKU]]="",0,Table110[[#This Row],[Quality Loss (T)]]/(Table110[[#This Row],[SOC (TPD)]]/24)),"") -> 0 | AK17: =IFERROR(IF(Table110[[#This Row],[SKU]]="",0,Table110[[#This Row],[Volume Delivered (T)]]/(Table110[[#This Row],[SOC (TPD)]]/24)),"") -> 20 | AL17: =IFERROR(Table110[[#This Row],[Operating Time]]/Table110[[#This Row],[PRODUCTION HOURS]],"") -> 0.87336245 | AM17: 94 | AN17: YES | AO17: YES | AP17: 1 | AQ17: 1 | AR17: 1 | AS17: =IFERROR(SUMIFS(#REF!,#REF!,'Shift Wise-Data Sheet'!A:A,#REF!,"Samridhi Perk Line")/SUMIFS(#REF!,#REF!,'Shift Wise-Data Sheet'!A:A,#REF!,"Samridhi Perk Line"),"") | AT17: 17 | AU17: 0 | AV17: =IFERROR(VLOOKUP(Table110[[#This Row],[Date]],'Overweight Data'!A15:G1110,6,FALSE),"") -> 0.023304105 | AW17: =IFERROR( IF( OR(Table110[[#This Row],[Operating Time]]=0, (Table110[[#This Row],[Operating Time]]/IF(AD17<=1,AD17+1,AD17))*60=0), 1, ((Table110[[#This Row],[Operating Time]])/IF(AD17<=1,AD17+1,AD17))*60 ), "_") -> 400 | AX17: =COUNTIFS('Downtime Data'!A:A,Table110[[#This Row],[Date]]) -> 2 | AY17: =IFERROR((SUM(Table110[[#This Row],[Minor Stoppages]:[Material Shortages]])/Table110[[#This Row],['# Stops]])*60,"") -> 90 | BA17: 46048
A18: 46035 | B18: =IF(A18="","",TEXT(A18,"dddddd")) -> Tuesday | D18: _10.3GM_HT | E18: {=IFERROR(INDIRECT(D18),"")} -> 34.2 | F18: 30 | G18: 32.7 | H18: =IFERROR((Table110[[#This Row],[Plan]]/Table110[[#This Row],[Hours Used]])/(Table110[[#This Row],[SOC (TPD)]]/24),"") -> 0.87719298 | I18: =IFERROR((Table110[[#This Row],[Volume Delivered (T)]]/Table110[[#This Row],[Hours Used]])/(Table110[[#This Row],[SOC (TPD)]]/24),"") -> 0.95614035 | M18: 1.362 | N18: 0.035 | R18: 0 | S18: 0 | T18: =IF(Table110[[#This Row],[SKU]]="",0,24-Table110[[#This Row],[Legal Non-Operating Time]]-Table110[[#This Row],[No Demand Time]]-Table110[[#This Row],[Force Majeure]]) -> 24 | AB18: =Table110[[#This Row],[Hours Used]]-SUM(Table110[[#This Row],[Planned Maintenance]:[Start and Finish Production]]) -> 24 | AI18: =(Table110[[#This Row],[Hours Used]]-SUM(Table110[[#This Row],[Planned Maintenance]:[Start and Finish Production]])-SUM(Table110[[#This Row],[Minor Stoppages]:[Material Shortages]])-Table110[[#This Row],[Quality Loss (Hrs)]]-Table110[[#This Row],[Operating Time]])/3 -> 0.032280702 | AJ18: =IFERROR(IF(Table110[[#This Row],[SKU]]="",0,Table110[[#This Row],[Quality Loss (T)]]/(Table110[[#This Row],[SOC (TPD)]]/24)),"") -> 0.95578947 | AK18: =IFERROR(IF(Table110[[#This Row],[SKU]]="",0,Table110[[#This Row],[Volume Delivered (T)]]/(Table110[[#This Row],[SOC (TPD)]]/24)),"") -> 22.947368 | AL18: =IFERROR(Table110[[#This Row],[Operating Time]]/Table110[[#This Row],[PRODUCTION HOURS]],"") -> 0.95614035 | AM18: 100 | AN18: YES | AO18: YES | AP18: 46 | AQ18: 45 | AS18: =IFERROR(SUMIFS(#REF!,#REF!,'Shift Wise-Data Sheet'!A:A,#REF!,"Samridhi Perk Line")/SUMIFS(#REF!,#REF!,'Shift Wise-Data Sheet'!A:A,#REF!,"Samridhi Perk Line"),"") | AT18: 21 | AU18: 0 | AV18: =IFERROR(VLOOKUP(Table110[[#This Row],[Date]],'Overweight Data'!A16:G1111,6,FALSE),"") -> 0.021852497 | AW18: =IFERROR( IF( OR(Table110[[#This Row],[Operating Time]]=0, (Table110[[#This Row],[Operating Time]]/IF(AD18<=1,AD18+1,AD18))*60=0), 1, ((Table110[[#This Row],[Operating Time]])/IF(AD18<=1,AD18+1,AD18))*60 ), "_") -> 1376.8421 | AX18: =COUNTIFS('Downtime Data'!A:A,Table110[[#This Row],[Date]]) -> 0 | AY18: =IFERROR((SUM(Table110[[#This Row],[Minor Stoppages]:[Material Shortages]])/Table110[[#This Row],['# Stops]])*60,"") | BA18: 46048
A19: 46036 | B19: =IF(A19="","",TEXT(A19,"dddddd")) -> Wednesday | D19: _10.3GM_HT | E19: {=IFERROR(INDIRECT(D19),"")} -> 34.2 | F19: 30 | G19: 30 | H19: =IFERROR((Table110[[#This Row],[Plan]]/Table110[[#This Row],[Hours Used]])/(Table110[[#This Row],[SOC (TPD)]]/24),"") -> 0.87719298 | I19: =IFERROR((Table110[[#This Row],[Volume Delivered (T)]]/Table110[[#This Row],[Hours Used]])/(Table110[[#This Row],[SOC (TPD)]]/24),"") -> 0.87719298 | M19: 2.127 | N19: 0.035 | R19: 0 | S19: 0 | T19: =IF(Table110[[#This Row],[SKU]]="",0,24-Table110[[#This Row],[Legal Non-Operating Time]]-Table110[[#This Row],[No Demand Time]]-Table110[[#This Row],[Force Majeure]]) -> 24 | X19: 1 | AB19: =Table110[[#This Row],[Hours Used]]-SUM(Table110[[#This Row],[Planned Maintenance]:[Start and Finish Production]]) -> 23 | AE19: 0.45 | AI19: =(Table110[[#This Row],[Hours Used]]-SUM(Table110[[#This Row],[Planned Maintenance]:[Start and Finish Production]])-SUM(Table110[[#This Row],[Minor Stoppages]:[Material Shortages]])-Table110[[#This Row],[Quality Loss (Hrs)]]-Table110[[#This Row],[Operating Time]])/3 -> 0.0015789474 | AJ19: =IFERROR(IF(Table110[[#This Row],[SKU]]="",0,Table110[[#This Row],[Quality Loss (T)]]/(Table110[[#This Row],[SOC (TPD)]]/24)),"") -> 1.4926316 | AK19: =IFERROR(IF(Table110[[#This Row],[SKU]]="",0,Table110[[#This Row],[Volume Delivered (T)]]/(Table110[[#This Row],[SOC (TPD)]]/24)),"") -> 21.052632 | AL19: =IFERROR(Table110[[#This Row],[Operating Time]]/Table110[[#This Row],[PRODUCTION HOURS]],"") -> 0.91533181 | AM19: 92 | AN19: YES | AO19: YES | AP19: 0 | AQ19: 0 | AS19: =IFERROR(SUMIFS(#REF!,#REF!,'Shift Wise-Data Sheet'!A:A,#REF!,"Samridhi Perk Line")/SUMIFS(#REF!,#REF!,'Shift Wise-Data Sheet'!A:A,#REF!,"Samridhi Perk Line"),"") | AT19: 18 | AU19: 0 | AV19: =IFERROR(VLOOKUP(Table110[[#This Row],[Date]],'Overweight Data'!A17:G1112,6,FALSE),"") -> 0.01962866 | AW19: =IFERROR( IF( OR(Table110[[#This Row],[Operating Time]]=0, (Table110[[#This Row],[Operating Time]]/IF(AD19<=1,AD19+1,AD19))*60=0), 1, ((Table110[[#This Row],[Operating Time]])/IF(AD19<=1,AD19+1,AD19))*60 ), "_") -> 1263.1579 | AX19: =COUNTIFS('Downtime Data'!A:A,Table110[[#This Row],[Date]]) -> 2 | AY19: =IFERROR((SUM(Table110[[#This Row],[Minor Stoppages]:[Material Shortages]])/Table110[[#This Row],['# Stops]])*60,"") -> 13.5 | BA19: 46048
A20: 46037 | B20: =IF(A20="","",TEXT(A20,"dddddd")) -> Thursday | D20: _10.3GM_HT | E20: {=IFERROR(INDIRECT(D20),"")} -> 34.2 | F20: 30 | G20: 31.5 | H20: =IFERROR((Table110[[#This Row],[Plan]]/Table110[[#This Row],[Hours Used]])/(Table110[[#This Row],[SOC (TPD)]]/24),"") -> 0.87719298 | I20: =IFERROR((Table110[[#This Row],[Volume Delivered (T)]]/Table110[[#This Row],[Hours Used]])/(Table110[[#This Row],[SOC (TPD)]]/24),"") -> 0.92105263 | N20: 0.035 | R20: 0 | S20: 0 | T20: =IF(Table110[[#This Row],[SKU]]="",0,24-Table110[[#This Row],[Legal Non-Operating Time]]-Table110[[#This Row],[No Demand Time]]-Table110[[#This Row],[Force Majeure]]) -> 24 | X20: 2.2 | AB20: =Table110[[#This Row],[Hours Used]]-SUM(Table110[[#This Row],[Planned Maintenance]:[Start and Finish Production]]) -> 21.8 | AI20: =(Table110[[#This Row],[Hours Used]]-SUM(Table110[[#This Row],[Planned Maintenance]:[Start and Finish Production]])-SUM(Table110[[#This Row],[Minor Stoppages]:[Material Shortages]])-Table110[[#This Row],[Quality Loss (Hrs)]]-Table110[[#This Row],[Operating Time]])/3 -> -0.10175439 | AJ20: =IFERROR(IF(Table110[[#This Row],[SKU]]="",0,Table110[[#This Row],[Quality Loss (T)]]/(Table110[[#This Row],[SOC (TPD)]]/24)),"") -> 0 | AK20: =IFERROR(IF(Table110[[#This Row],[SKU]]="",0,Table110[[#This Row],[Volume Delivered (T)]]/(Table110[[#This Row],[SOC (TPD)]]/24)),"") -> 22.105263 | AL20: =IFERROR(Table110[[#This Row],[Operating Time]]/Table110[[#This Row],[PRODUCTION HOURS]],"") -> 1.0140029 | AM20: 114 | AN20: YES | AO20: YES | AP20: 2 | AQ20: 2 | AS20: =IFERROR(SUMIFS(#REF!,#REF!,'Shift Wise-Data Sheet'!A:A,#REF!,"Samridhi Perk Line")/SUMIFS(#REF!,#REF!,'Shift Wise-Data Sheet'!A:A,#REF!,"Samridhi Perk Line"),"") | AT20: 7 | AU20: 0 | AV20: =IFERROR(VLOOKUP(Table110[[#This Row],[Date]],'Overweight Data'!A18:G1113,6,FALSE),"") -> 0.023287293 | AW20: =IFERROR( IF( OR(Table110[[#This Row],[Operating Time]]=0, (Table110[[#This Row],[Operating Time]]/IF(AD20<=1,AD20+1,AD20))*60=0), 1, ((Table110[[#This Row],[Operating Time]])/IF(AD20<=1,AD20+1,AD20))*60 ), "_") -> 1326.3158 | AX20: =COUNTIFS('Downtime Data'!A:A,Table110[[#This Row],[Date]]) -> 1 | AY20: =IFERROR((SUM(Table110[[#This Row],[Minor Stoppages]:[Material Shortages]])/Table110[[#This Row],['# Stops]])*60,"") -> 0 | BA20: 46048
A21: 46038 | B21: =IF(A21="","",TEXT(A21,"dddddd")) -> Friday | D21: _10.3GM | E21: {=IFERROR(INDIRECT(D21),"")} -> 39.2 | F21: 32 | G21: 38.6 | H21: =IFERROR((Table110[[#This Row],[Plan]]/Table110[[#This Row],[Hours Used]])/(Table110[[#This Row],[SOC (TPD)]]/24),"") -> 0.81632653 | I21: =IFERROR((Table110[[#This Row],[Volume Delivered (T)]]/Table110[[#This Row],[Hours Used]])/(Table110[[#This Row],[SOC (TPD)]]/24),"") -> 0.98469388 | N21: 0.035 | R21: 0 | S21: 0 | T21: =IF(Table110[[#This Row],[SKU]]="",0,24-Table110[[#This Row],[Legal Non-Operating Time]]-Table110[[#This Row],[No Demand Time]]-Table110[[#This Row],[Force Majeure]]) -> 24 | AB21: =Table110[[#This Row],[Hours Used]]-SUM(Table110[[#This Row],[Planned Maintenance]:[Start and Finish Production]]) -> 24 | AI21: =(Table110[[#This Row],[Hours Used]]-SUM(Table110[[#This Row],[Planned Maintenance]:[Start and Finish Production]])-SUM(Table110[[#This Row],[Minor Stoppages]:[Material Shortages]])-Table110[[#This Row],[Quality Loss (Hrs)]]-Table110[[#This Row],[Operating Time]])/3 -> 0.12244898 | AJ21: =IFERROR(IF(Table110[[#This Row],[SKU]]="",0,Table110[[#This Row],[Quality Loss (T)]]/(Table110[[#This Row],[SOC (TPD)]]/24)),"") -> 0 | AK21: =IFERROR(IF(Table110[[#This Row],[SKU]]="",0,Table110[[#This Row],[Volume Delivered (T)]]/(Table110[[#This Row],[SOC (TPD)]]/24)),"") -> 23.632653 | AL21: =IFERROR(Table110[[#This Row],[Operating Time]]/Table110[[#This Row],[PRODUCTION HOURS]],"") -> 0.98469388 | AM21: 119 | AN21: YES | AO21: YES | AP21: 0 | AQ21: 0 | AS21: =IFERROR(SUMIFS(#REF!,#REF!,'Shift Wise-Data Sheet'!A:A,#REF!,"Samridhi Perk Line")/SUMIFS(#REF!,#REF!,'Shift Wise-Data Sheet'!A:A,#REF!,"Samridhi Perk Line"),"") | AT21: 8 | AU21: 0 | AV21: =IFERROR(VLOOKUP(Table110[[#This Row],[Date]],'Overweight Data'!A19:G1114,6,FALSE),"") -> 0.02558011 | AW21: =IFERROR( IF( OR(Table110[[#This Row],[Operating Time]]=0, (Table110[[#This Row],[Operating Time]]/IF(AD21<=1,AD21+1,AD21))*60=0), 1, ((Table110[[#This Row],[Operating Time]])/IF(AD21<=1,AD21+1,AD21))*60 ), "_") -> 1417.9592 | AX21: =COUNTIFS('Downtime Data'!A:A,Table110[[#This Row],[Date]]) -> 0 | AY21: =IFERROR((SUM(Table110[[#This Row],[Minor Stoppages]:[Material Shortages]])/Table110[[#This Row],['# Stops]])*60,"") | BA21: 46048
A22: 46039 | B22: =IF(A22="","",TEXT(A22,"dddddd")) -> Saturday | D22: _10.3GM | E22: {=IFERROR(INDIRECT(D22),"")} -> 39.2 | F22: 32 | G22: 35.2 | H22: =IFERROR((Table110[[#This Row],[Plan]]/Table110[[#This Row],[Hours Used]])/(Table110[[#This Row],[SOC (TPD)]]/24),"") -> 0.81632653 | I22: =IFERROR((Table110[[#This Row],[Volume Delivered (T)]]/Table110[[#This Row],[Hours Used]])/(Table110[[#This Row],[SOC (TPD)]]/24),"") -> 0.89795918 | M22: 0.2 | N22: 0.035 | R22: 0 | S22: 0 | T22: =IF(Table110[[#This Row],[SKU]]="",0,24-Table110[[#This Row],[Legal Non-Operating Time]]-Table110[[#This Row],[No Demand Time]]-Table110[[#This Row],[Force Majeure]]) -> 24 | AB22: =Table110[[#This Row],[Hours Used]]-SUM(Table110[[#This Row],[Planned Maintenance]:[Start and Finish Production]]) -> 24 | AE22: 1 | AI22: =(Table110[[#This Row],[Hours Used]]-SUM(Table110[[#This Row],[Planned Maintenance]:[Start and Finish Production]])-SUM(Table110[[#This Row],[Minor Stoppages]:[Material Shortages]])-Table110[[#This Row],[Quality Loss (Hrs)]]-Table110[[#This Row],[Operating Time]])/3 -> 0.44217687 | AJ22: =IFERROR(IF(Table110[[#This Row],[SKU]]="",0,Table110[[#This Row],[Quality Loss (T)]]/(Table110[[#This Row],[SOC (TPD)]]/24)),"") -> 0.12244898 | AK22: =IFERROR(IF(Table110[[#This Row],[SKU]]="",0,Table110[[#This Row],[Volume Delivered (T)]]/(Table110[[#This Row],[SOC (TPD)]]/24)),"") -> 21.55102 | AL22: =IFERROR(Table110[[#This Row],[Operating Time]]/Table110[[#This Row],[PRODUCTION HOURS]],"") -> 0.89795918 | AM22: 111 | AN22: YES | AO22: YES | AP22: 0 | AQ22: 0 | AS22: =IFERROR(SUMIFS(#REF!,#REF!,'Shift Wise-Data Sheet'!A:A,#REF!,"Samridhi Perk Line")/SUMIFS(#REF!,#REF!,'Shift Wise-Data Sheet'!A:A,#REF!,"Samridhi Perk Line"),"") | AT22: 35 | AU22: 0 | AV22: =IFERROR(VLOOKUP(Table110[[#This Row],[Date]],'Overweight Data'!A20:G1115,6,FALSE),"") -> 0.031058932 | AW22: =IFERROR( IF( OR(Table110[[#This Row],[Operating Time]]=0, (Table110[[#This Row],[Operating Time]]/IF(AD22<=1,AD22+1,AD22))*60=0), 1, ((Table110[[#This Row],[Operating Time]])/IF(AD22<=1,AD22+1,AD22))*60 ), "_") -> 1293.0612 | AX22: =COUNTIFS('Downtime Data'!A:A,Table110[[#This Row],[Date]]) -> 1 | AY22: =IFERROR((SUM(Table110[[#This Row],[Minor Stoppages]:[Material Shortages]])/Table110[[#This Row],['# Stops]])*60,"") -> 60 | BA22: 46048
A23: 46040 | B23: =IF(A23="","",TEXT(A23,"dddddd")) -> Sunday | D23: _10.3GM | E23: {=IFERROR(INDIRECT(D23),"")} -> 39.2 | F23: 32 | G23: 32.59 | H23: =IFERROR((Table110[[#This Row],[Plan]]/Table110[[#This Row],[Hours Used]])/(Table110[[#This Row],[SOC (TPD)]]/24),"") -> 0.81632653 | I23: =IFERROR((Table110[[#This Row],[Volume Delivered (T)]]/Table110[[#This Row],[Hours Used]])/(Table110[[#This Row],[SOC (TPD)]]/24),"") -> 0.83137755 | M23: 1.72 | N23: 0.035 | R23: 0 | S23: 0 | T23: =IF(Table110[[#This Row],[SKU]]="",0,24-Table110[[#This Row],[Legal Non-Operating Time]]-Table110[[#This Row],[No Demand Time]]-Table110[[#This Row],[Force Majeure]]) -> 24 | AB23: =Table110[[#This Row],[Hours Used]]-SUM(Table110[[#This Row],[Planned Maintenance]:[Start and Finish Production]]) -> 24 | AC23: 0.5 | AD23: 1 | AE23: 0.75 | AI23: =(Table110[[#This Row],[Hours Used]]-SUM(Table110[[#This Row],[Planned Maintenance]:[Start and Finish Production]])-SUM(Table110[[#This Row],[Minor Stoppages]:[Material Shortages]])-Table110[[#This Row],[Quality Loss (Hrs)]]-Table110[[#This Row],[Operating Time]])/3 -> 0.24795918 | AJ23: =IFERROR(IF(Table110[[#This Row],[SKU]]="",0,Table110[[#This Row],[Quality Loss (T)]]/(Table110[[#This Row],[SOC (TPD)]]/24)),"") -> 1.0530612 | AK23: =IFERROR(IF(Table110[[#This Row],[SKU]]="",0,Table110[[#This Row],[Volume Delivered (T)]]/(Table110[[#This Row],[SOC (TPD)]]/24)),"") -> 19.953061 | AL23: =IFERROR(Table110[[#This Row],[Operating Time]]/Table110[[#This Row],[PRODUCTION HOURS]],"") -> 0.83137755 | AM23: 97 | AN23: YES | AO23: YES | AP23: 0 | AQ23: 0 | AS23: =IFERROR(SUMIFS(#REF!,#REF!,'Shift Wise-Data Sheet'!A:A,#REF!,"Samridhi Perk Line")/SUMIFS(#REF!,#REF!,'Shift Wise-Data Sheet'!A:A,#REF!,"Samridhi Perk Line"),"") | AT23: 2 | AU23: 0 | AV23: =IFERROR(VLOOKUP(Table110[[#This Row],[Date]],'Overweight Data'!A21:G1116,6,FALSE),"") -> 0.018075506 | AW23: =IFERROR( IF( OR(Table110[[#This Row],[Operating Time]]=0, (Table110[[#This Row],[Operating Time]]/IF(AD23<=1,AD23+1,AD23))*60=0), 1, ((Table110[[#This Row],[Operating Time]])/IF(AD23<=1,AD23+1,AD23))*60 ), "_") -> 598.59184 | AX23: =COUNTIFS('Downtime Data'!A:A,Table110[[#This Row],[Date]]) -> 4 | AY23: =IFERROR((SUM(Table110[[#This Row],[Minor Stoppages]:[Material Shortages]])/Table110[[#This Row],['# Stops]])*60,"") -> 33.75 | BA23: 46048
A24: 46041 | B24: =IF(A24="","",TEXT(A24,"dddddd")) -> Monday | D24: _10.3GM | E24: {=IFERROR(INDIRECT(D24),"")} -> 39.2 | F24: 32 | G24: 31.8 | H24: =IFERROR((Table110[[#This Row],[Plan]]/Table110[[#This Row],[Hours Used]])/(Table110[[#This Row],[SOC (TPD)]]/24),"") -> 0.81632653 | I24: =IFERROR((Table110[[#This Row],[Volume Delivered (T)]]/Table110[[#This Row],[Hours Used]])/(Table110[[#This Row],[SOC (TPD)]]/24),"") -> 0.81122449 | M24: 2.048 | N24: 0.035 | R24: 3 | S24: 3 | T24: =IF(Table110[[#This Row],[SKU]]="",0,24-Table110[[#This Row],[Legal Non-Operating Time]]-Table110[[#This Row],[No Demand Time]]-Table110[[#This Row],[Force Majeure]]) -> 24 | AB24: =Table110[[#This Row],[Hours Used]]-SUM(Table110[[#This Row],[Planned Maintenance]:[Start and Finish Production]]) -> 24 | AC24: 1 | AD24: 0.5 | AE24: 1 | AI24: =(Table110[[#This Row],[Hours Used]]-SUM(Table110[[#This Row],[Planned Maintenance]:[Start and Finish Production]])-SUM(Table110[[#This Row],[Minor Stoppages]:[Material Shortages]])-Table110[[#This Row],[Quality Loss (Hrs)]]-Table110[[#This Row],[Operating Time]])/3 -> 0.25891156 | AJ24: =IFERROR(IF(Table110[[#This Row],[SKU]]="",0,Table110[[#This Row],[Quality Loss (T)]]/(Table110[[#This Row],[SOC (TPD)]]/24)),"") -> 1.2538776 | AK24: =IFERROR(IF(Table110[[#This Row],[SKU]]="",0,Table110[[#This Row],[Volume Delivered (T)]]/(Table110[[#This Row],[SOC (TPD)]]/24)),"") -> 19.469388 | AL24: =IFERROR(Table110[[#This Row],[Operating Time]]/Table110[[#This Row],[PRODUCTION HOURS]],"") -> 0.81122449 | AM24: 84 | AN24: YES | AO24: YES | AP24: 3 | AQ24: 0 | AS24: =IFERROR(SUMIFS(#REF!,#REF!,'Shift Wise-Data Sheet'!A:A,#REF!,"Samridhi Perk Line")/SUMIFS(#REF!,#REF!,'Shift Wise-Data Sheet'!A:A,#REF!,"Samridhi Perk Line"),"") | AT24: 7 | AU24: 0 | AV24: =IFERROR(VLOOKUP(Table110[[#This Row],[Date]],'Overweight Data'!A22:G1117,6,FALSE),"") -> 0.020856354 | AW24: =IFERROR( IF( OR(Table110[[#This Row],[Operating Time]]=0, (Table110[[#This Row],[Operating Time]]/IF(AD24<=1,AD24+1,AD24))*60=0), 1, ((Table110[[#This Row],[Operating Time]])/IF(AD24<=1,AD24+1,AD24))*60 ), "_") -> 778.77551 | AX24: =COUNTIFS('Downtime Data'!A:A,Table110[[#This Row],[Date]]) -> 3 | AY24: =IFERROR((SUM(Table110[[#This Row],[Minor Stoppages]:[Material Shortages]])/Table110[[#This Row],['# Stops]])*60,"") -> 50 | BA24: 46048
